<?xml version="1.0"?>
<robot name="origins">
  <link name="base_link">
    <visual>
      <geometry>
        <box size="0.2 0.2 0.05"/>
      </geometry>
    </visual>
    <collision>
      <geometry>
        <box size="0.2 0.2 0.05"/>
      </geometry>
    </collision>
    <inertial>
      <mass value="2"/>
      <inertia ixx="1.0" ixy="0.0" ixz="0.0" iyy="1.0" iyz="0.0" izz="1.0"/>
    </inertial>
  </link>

  <link name="wheel_0">
    <visual>
      <geometry>
        <cylinder length="0.02" radius="0.08"/>
      </geometry>
      <origin rpy="0 1.57075 0" xyz="0. 0 0.0"/>
    </visual>
    <collision>
      <geometry>
        <cylinder length="0.02" radius="0.08"/>
      </geometry>
      <origin rpy="0 1.57075 0" xyz="0. 0 0.0"/>
    </collision>
    <inertial>
      <mass value="0.1"/>
      <inertia ixx="1.0" ixy="0.0" ixz="0.0" iyy="1.0" iyz="0.0" izz="1.0"/>
      <origin rpy="0 1.57075 0" xyz="0. 0 0.0"/>
    </inertial>
  </link>

  <joint name="base_to_wheel_0" type="continuous">
    <axis rpy="0 1.57075 0" xyz="1 0 0"/>
    <parent link="base_link"/>
    <child link="wheel_0"/>
    <origin xyz="0.1 0 0.0"/>
  </joint>

  <link name="wheel_1">
    <visual>
      <geometry>
        <cylinder length="0.02" radius="0.08"/>
      </geometry>
      <origin rpy="0 1.57075 0" xyz="-0. 0 0.0"/>
    </visual>
    <collision>
      <geometry>
        <cylinder length="0.02" radius="0.08"/>
      </geometry>
      <origin rpy="0 1.57075 0" xyz="-0. 0 0.0"/>
    </collision>
    <inertial>
      <mass value="0.1"/>
      <inertia ixx="1.0" ixy="0.0" ixz="0.0" iyy="1.0" iyz="0.0" izz="1.0"/>
      <origin rpy="0 1.57075 0" xyz="-0.1 0 0.0"/>
    </inertial>
  </link>

  <joint name="base_to_wheel_1" type="continuous">
    <axis rpy="0 1.57075 0" xyz="1 0 0"/>
    <parent link="base_link"/>
    <child link="wheel_1"/>
    <origin xyz="-0.2 0 0.0"/>
  </joint>

  <ros2_control name="GazeboSystem" type="system">
    <hardware>
      <plugin>gazebo_ros2_control/GazeboSystem</plugin>
    </hardware>
    <joint name="base_to_wheel_0">
      <command_interface name="effort">
        <param name="min">-1000</param>
        <param name="max">1000</param>
      </command_interface>
      <state_interface name="position">
        <param name="initial_value">0.0</param>
      </state_interface>
      <state_interface name="velocity"/>
      <state_interface name="effort"/>
    </joint>
    <joint name="base_to_wheel_1">
      <command_interface name="effort">
        <param name="min">-1000</param>
        <param name="max">1000</param>
      </command_interface>
      <state_interface name="position">
        <param name="initial_value">0.0</param>
      </state_interface>
      <state_interface name="velocity"/>
      <state_interface name="effort"/>
    </joint>
  </ros2_control>

  <gazebo>
    <plugin filename="libgazebo_ros2_control.so" name="gazebo_ros2_control">
      <parameters>$(find snow_sim)/config/snow.yaml</parameters>
    </plugin>
  </gazebo>

</robot>
