<?xml version="1.0" encoding="utf-8"?>

<robot
  name="snow_collision_v3">
  <link
    name="base_link">
    <inertial>
      <origin
        xyz="-5.55111512312578E-17 1.66533453693773E-16 0.0431969168006088"
        rpy="0 0 0" />
      <mass
        value="0.404000000070774" />
      <inertia
        ixx="0.00166450539529181"
        ixy="1.0842021724855E-19"
        ixz="-4.45778007407081E-20"
        iyy="0.00166450539529181"
        iyz="-7.35966516607639E-21"
        izz="0.00317940661394847" />
    </inertial>
    <visual>
      <origin
        xyz="0 0 0"
        rpy="0 0 0" />
      <geometry>
        <mesh
          filename="file://$(find snow_sim)/meshes_visual/base_link.STL" />
      </geometry>
      <material
        name="">
        <color
          rgba="0.698039215686274 0.698039215686274 0.698039215686274 1" />
      </material>
    </visual>
    <collision>
      <origin
        xyz="0 0 0"
        rpy="0 0 0" />
      <geometry>
        <mesh
          filename="file://$(find snow_sim)/meshes_collision/base_link.STL" />
      </geometry>
    </collision>
  </link>
  <link
    name="wm1_base">
    <inertial>
      <origin
        xyz="0.00795370777004065 0.0546227553283528 0.0265672262517407"
        rpy="0 0 0" />
      <mass
        value="0.10699000447605" />
      <inertia
        ixx="0.000107088332273698"
        ixy="-1.18802505025781E-05"
        ixz="9.3279964993511E-07"
        iyy="0.000107088332273698"
        iyz="9.32799649935108E-07"
        izz="0.000101581821488796" />
    </inertial>
    <visual>
      <origin
        xyz="0 0 0"
        rpy="0 0 0" />
      <geometry>
        <mesh
          filename="file://$(find snow_sim)/meshes_visual/wm1_base.STL" />
      </geometry>
      <material
        name="">
        <color
          rgba="0.698039215686274 0.698039215686274 0.698039215686274 1" />
      </material>
    </visual>
    <collision>
      <origin
        xyz="0 0 0"
        rpy="0 0 0" />
      <geometry>
        <mesh
          filename="file://$(find snow_sim)/meshes_collision/wm1_base.STL" />
      </geometry>
    </collision>
  </link>
  <joint
    name="base_link_to_wm1_base"
    type="fixed">
    <origin
      xyz="0.103767920139126 0.0570988725808139 0.014"
      rpy="0 0 0" />
    <parent
      link="base_link" />
    <child
      link="wm1_base" />
    <axis
      xyz="0 0 0" />
  </joint>
  <link
    name="wm1_break_enc">
    <inertial>
      <origin
        xyz="0 0 0.02335"
        rpy="0 0 0" />
      <mass
        value="0.4207" />
      <inertia
        ixx="0.0001606"
        ixy="0"
        ixz="3.9151E-37"
        iyy="0.0001606"
        iyz="-3.9151E-37"
        izz="0.00016828" />
    </inertial>
    <visual>
      <origin
        xyz="0 0 0"
        rpy="0 0 0" />
      <geometry>
        <mesh
          filename="file://$(find snow_sim)/meshes_visual/wm1_brake_enc.STL" />
      </geometry>
      <material
        name="">
        <color
          rgba="0.69804 0.69804 0.69804 1" />
      </material>
    </visual>
    <collision>
      <origin
        xyz="0 0 0"
        rpy="0 0 0" />
      <geometry>
        <mesh
          filename="file://$(find snow_sim)/meshes_collision/wm1_break_enc.STL" />
      </geometry>
    </collision>
  </link>
  <joint
    name="wm1_base_to_break_enc"
    type="fixed">
    <origin
      xyz="0.0247487373415291 0.0714177848998412 0.058"
      rpy="0 0 0" />
    <parent
      link="wm1_base" />
    <child
      link="wm1_break_enc" />
    <axis
      xyz="0 0 0" />
  </joint>
  <link
    name="wm1_steering_axis">
    <inertial>
      <origin
        xyz="5.55111512312578E-17 5.55111512312578E-17 0.051"
        rpy="0 0 0" />
      <mass
        value="0.0731981137116207" />
      <inertia
        ixx="6.37411004153637E-05"
        ixy="0"
        ixz="-1.94435145871703E-38"
        iyy="6.37411004153637E-05"
        iyz="-1.2707676790361E-38"
        izz="5.56671654776875E-07" />
    </inertial>
    <visual>
      <origin
        xyz="0 0 0"
        rpy="0 0 0" />
      <geometry>
        <mesh
          filename="file://$(find snow_sim)/meshes_visual/wm1_steering_axis.STL" />
      </geometry>
      <material
        name="">
        <color
          rgba="0.698039215686274 0.698039215686274 0.698039215686274 1" />
      </material>
    </visual>
    <collision>
      <origin
        xyz="0 0 0"
        rpy="0 0 0" />
      <geometry>
        <mesh
          filename="file://$(find snow_sim)/meshes_collision/wm1_steering_axis.STL" />
      </geometry>
    </collision>
  </link>
  <joint
    name="wm1_base_to_steering_axis"
    type="revolute">
    <origin
      xyz="0.0247487373415291 0.0714177848998412 0"
      rpy="0 0 0" />
    <parent
      link="wm1_base" />
    <child
      link="wm1_steering_axis" />
    <axis
      xyz="0 0 -1" />
    <limit
      lower="-0.7854"
      upper="2.3562"
      effort="1000"
      velocity="0.5" />
    <dynamics 
      damping="1.00" 
      friction="1.00"/>
  </joint>
  <link
    name="wm1_arm">
    <inertial>
      <origin
        xyz="5.55111512312578E-17 0.0479626000129808 0.0356051741170328"
        rpy="0 0 0" />
      <mass
        value="0.227000002375456" />
      <inertia
        ixx="0.0002654967989859"
        ixy="7.45388993583784E-20"
        ixz="1.6940658945086E-20"
        iyy="0.00010668622732319"
        iyz="-2.88668700742115E-05"
        izz="0.000250479546891119" />
    </inertial>
    <visual>
      <origin
        xyz="0 0 0"
        rpy="0 0 0" />
      <geometry>
        <mesh
          filename="file://$(find snow_sim)/meshes_visual/wm1_arm.STL" />
      </geometry>
      <material
        name="">
        <color
          rgba="0.698039215686274 0.698039215686274 0.698039215686274 1" />
      </material>
    </visual>
    <collision>
      <origin
        xyz="0 0 0"
        rpy="0 0 0" />
      <geometry>
        <mesh
          filename="file://$(find snow_sim)/meshes_collision/wm1_arm.STL" />
      </geometry>
    </collision>
  </link>
  <joint
    name="wm1_steering_axis_to_arm"
    type="fixed">
    <origin
      xyz="0 0 0"
      rpy="0 0 0" />
    <parent
      link="wm1_steering_axis" />
    <child
      link="wm1_arm" />
    <axis
      xyz="0 0 0" />
  </joint>
  <link
    name="wm1_wheel">
    <inertial>
      <origin
        xyz="5.5511E-17 -2.7756E-17 -0.026187"
        rpy="0 0 0" />
      <mass
        value="0.18198" />
      <inertia
        ixx="8.4567E-05"
        ixy="1.7241E-21"
        ixz="4.7434E-20"
        iyy="8.4567E-05"
        iyz="1.4895E-22"
        izz="0.00015944" />
    </inertial>
    <visual>
      <origin
        xyz="0 0 0"
        rpy="0 0 0" />
      <geometry>
        <mesh
          filename="file://$(find snow_sim)/meshes_visual/wm1_wheel.STL" />
      </geometry>
      <material
        name="">
        <color
          rgba="0.69804 0.69804 0.69804 1" />
      </material>
    </visual>
    <collision>
      <origin
        xyz="0 0 -0.0275"
        rpy="0 3.14159265358979 0" />
      <geometry>
        <cylinder length="0.012" radius="0.044"/>
      </geometry>
    </collision>
  </link>
  <joint
    name="wm1_arm_to_wheel"
    type="continuous">
    <origin
      xyz="0 0.09115 0.03"
      rpy="1.5707963267949 0 0" />
    <parent
      link="wm1_arm" />
    <child
      link="wm1_wheel" />
    <axis
      xyz="0 0 -1" />
  </joint>
  <link
    name="wm2_base">
    <inertial>
      <origin
        xyz="0.0546227553283528 -0.00795370777004065 0.0265672262517407"
        rpy="0 0 0" />
      <mass
        value="0.10699000447605" />
      <inertia
        ixx="0.000107088332273698"
        ixy="1.18802505025781E-05"
        ixz="9.32799649935097E-07"
        iyy="0.000107088332273698"
        iyz="-9.32799649935091E-07"
        izz="0.000101581821488797" />
    </inertial>
    <visual>
      <origin
        xyz="0 0 0"
        rpy="0 0 0" />
      <geometry>
        <mesh
          filename="file://$(find snow_sim)/meshes_visual/wm2_base.STL" />
      </geometry>
      <material
        name="">
        <color
          rgba="0.698039215686274 0.698039215686274 0.698039215686274 1" />
      </material>
    </visual>
    <collision>
      <origin
        xyz="0 0 0"
        rpy="0 0 0" />
      <geometry>
        <mesh
          filename="file://$(find snow_sim)/meshes_collision/wm2_base.STL" />
      </geometry>
    </collision>
  </link>
  <joint
    name="base_link_to_wm2_base"
    type="fixed">
    <origin
      xyz="0.0570988725808137 -0.103767920139126 0.014"
      rpy="0 0 0" />
    <parent
      link="base_link" />
    <child
      link="wm2_base" />
    <axis
      xyz="0 0 0" />
  </joint>
  <link
    name="wm2_break_enc">
    <inertial>
      <origin
        xyz="0 -2.77555756156289E-17 0.02335"
        rpy="0 0 0" />
      <mass
        value="0.420699883079902" />
      <inertia
        ixx="0.000160598323950158"
        ixy="-1.35525271560688E-20"
        ixz="-1.9623051723885E-36"
        iyy="0.000160598323950158"
        iyz="1.17928417727503E-36"
        izz="0.000168279953231961" />
    </inertial>
    <visual>
      <origin
        xyz="0 0 0"
        rpy="0 0 0" />
      <geometry>
        <mesh
          filename="file://$(find snow_sim)/meshes_visual/wm2_brake_enc.STL" />
      </geometry>
      <material
        name="">
        <color
          rgba="0.698039215686274 0.698039215686274 0.698039215686274 1" />
      </material>
    </visual>
    <collision>
      <origin
        xyz="0 0 0"
        rpy="0 0 0" />
      <geometry>
        <mesh
          filename="file://$(find snow_sim)/meshes_collision/wm2_break_enc.STL" />
      </geometry>
    </collision>
  </link>
  <joint
    name="wm2_base_to_break_enc"
    type="fixed">
    <origin
      xyz="0.0714177848998414 -0.0247487373415292 0.058"
      rpy="0 0 0" />
    <parent
      link="wm2_base" />
    <child
      link="wm2_break_enc" />
    <axis
      xyz="0 0 0" />
  </joint>
  <link
    name="wm2_steering_axis">
    <inertial>
      <origin
        xyz="5.55111512312578E-17 2.77555756156289E-17 0.051"
        rpy="0 0 0" />
      <mass
        value="0.0731981137116207" />
      <inertia
        ixx="6.37411004153636E-05"
        ixy="0"
        ixz="-2.03996247049784E-39"
        iyy="6.37411004153636E-05"
        iyz="6.64677121861692E-38"
        izz="5.56671654776875E-07" />
    </inertial>
    <visual>
      <origin
        xyz="0 0 0"
        rpy="0 0 0" />
      <geometry>
        <mesh
          filename="file://$(find snow_sim)/meshes_visual/wm2_steering_axis.STL" />
      </geometry>
      <material
        name="">
        <color
          rgba="0.698039215686274 0.698039215686274 0.698039215686274 1" />
      </material>
    </visual>
    <collision>
      <origin
        xyz="0 0 0"
        rpy="0 0 0" />
      <geometry>
        <mesh
          filename="file://$(find snow_sim)/meshes_collision/wm2_steering_axis.STL" />
      </geometry>
    </collision>
  </link>
  <joint
    name="wm2_base_to_steering_axis"
    type="revolute">
    <origin
      xyz="0.0714177848998414 -0.0247487373415292 0"
      rpy="0 0 0" />
    <parent
      link="wm2_base" />
    <child
      link="wm2_steering_axis" />
    <axis
      xyz="0 0 1" />
    <limit
      lower="-0.7854"
      upper="2.3562"
      effort="1000"
      velocity="0" />
    <dynamics 
      damping="1.00" 
      friction="1.00"/>
  </joint>
  <link
    name="wm2_arm">
    <inertial>
      <origin
        xyz="5.55111512312578E-17 -0.0479626000129807 0.0356051741170328"
        rpy="0 0 0" />
      <mass
        value="0.227000002375456" />
      <inertia
        ixx="0.0002654967989859"
        ixy="5.75982404132924E-20"
        ixz="-2.87991202066462E-20"
        iyy="0.00010668622732319"
        iyz="2.88668700742115E-05"
        izz="0.000250479546891119" />
    </inertial>
    <visual>
      <origin
        xyz="0 0 0"
        rpy="0 0 0" />
      <geometry>
        <mesh
          filename="file://$(find snow_sim)/meshes_visual/wm2_arm.STL" />
      </geometry>
      <material
        name="">
        <color
          rgba="0.698039215686274 0.698039215686274 0.698039215686274 1" />
      </material>
    </visual>
    <collision>
      <origin
        xyz="0 0 0"
        rpy="0 0 0" />
      <geometry>
        <mesh
          filename="file://$(find snow_sim)/meshes_collision/wm2_arm.STL" />
      </geometry>
    </collision>
  </link>
  <joint
    name="wm2_steering_axis_to_arm"
    type="fixed">
    <origin
      xyz="0 0 0"
      rpy="0 0 0" />
    <parent
      link="wm2_steering_axis" />
    <child
      link="wm2_arm" />
    <axis
      xyz="0 0 0" />
  </joint>
  <link
    name="wm2_wheel">
    <inertial>
      <origin
        xyz="-2.7756E-17 0 0.026187"
        rpy="0 0 0" />
      <mass
        value="0.18198" />
      <inertia
        ixx="8.4567E-05"
        ixy="-1.4026E-21"
        ixz="1.3553E-20"
        iyy="8.4567E-05"
        iyz="-3.569E-21"
        izz="0.00015944" />
    </inertial>
    <visual>
      <origin
        xyz="0 0 0"
        rpy="0 0 0" />
      <geometry>
        <mesh
          filename="file://$(find snow_sim)/meshes_visual/wm2_wheel.STL" />
      </geometry>
      <material
        name="">
        <color
          rgba="0.69804 0.69804 0.69804 1" />
      </material>
    </visual>
    <collision>
      <origin
        xyz="0 0 0.0275"
        rpy="0 0 0" />
      <geometry>
        <cylinder length="0.012" radius="0.044"/>
      </geometry>
    </collision>
  </link>
  <joint
    name="wm2_arm_to_wheel"
    type="continuous">
    <origin
      xyz="0 -0.09115 0.03"
      rpy="1.5707963267949 0 0" />
    <parent
      link="wm2_arm" />
    <child
      link="wm2_wheel" />
    <axis
      xyz="0 0 -1" />
  </joint>
  <link
    name="wm3_base">
    <inertial>
      <origin
        xyz="-0.00795370777004027 -0.0546227553283529 0.0265672262517407"
        rpy="0 0 0" />
      <mass
        value="0.10699000447605" />
      <inertia
        ixx="0.000107088332273698"
        ixy="-1.18802505025781E-05"
        ixz="-9.32799649935088E-07"
        iyy="0.000107088332273697"
        iyz="-9.3279964993511E-07"
        izz="0.000101581821488797" />
    </inertial>
    <visual>
      <origin
        xyz="0 0 0"
        rpy="0 0 0" />
      <geometry>
        <mesh
          filename="file://$(find snow_sim)/meshes_visual/wm3_base.STL" />
      </geometry>
      <material
        name="">
        <color
          rgba="0.698039215686274 0.698039215686274 0.698039215686274 1" />
      </material>
    </visual>
    <collision>
      <origin
        xyz="0 0 0"
        rpy="0 0 0" />
      <geometry>
        <mesh
          filename="file://$(find snow_sim)/meshes_collision/wm3_base.STL" />
      </geometry>
    </collision>
  </link>
  <joint
    name="base_link_to_wm3_base"
    type="fixed">
    <origin
      xyz="-0.103767920139127 -0.0570988725808137 0.014"
      rpy="0 0 0" />
    <parent
      link="base_link" />
    <child
      link="wm3_base" />
    <axis
      xyz="0 0 0" />
  </joint>
  <link
    name="wm3_break_enc">
    <inertial>
      <origin
        xyz="0 0 0.02335"
        rpy="0 0 0" />
      <mass
        value="0.420699883079902" />
      <inertia
        ixx="0.000160598323950158"
        ixy="1.35525271560688E-20"
        ixz="-3.48117094068921E-21"
        iyy="0.000160598323950158"
        iyz="-3.48117094068926E-21"
        izz="0.000168279953231961" />
    </inertial>
    <visual>
      <origin
        xyz="0 0 0"
        rpy="0 0 0" />
      <geometry>
        <mesh
          filename="file://$(find snow_sim)/meshes_visual/wm3_brake_enc.STL" />
      </geometry>
      <material
        name="">
        <color
          rgba="0.698039215686274 0.698039215686274 0.698039215686274 1" />
      </material>
    </visual>
    <collision>
      <origin
        xyz="0 0 0"
        rpy="0 0 0" />
      <geometry>
        <mesh
          filename="file://$(find snow_sim)/meshes_collision/wm3_break_enc.STL" />
      </geometry>
    </collision>
  </link>
  <joint
    name="wm3_base_to_break_enc"
    type="fixed">
    <origin
      xyz="-0.0247487373415287 -0.0714177848998415 0.058"
      rpy="0 0 0" />
    <parent
      link="wm3_base" />
    <child
      link="wm3_break_enc" />
    <axis
      xyz="0 0 0" />
  </joint>
  <link
    name="wm3_steering_axis">
    <inertial>
      <origin
        xyz="0 0 0.051"
        rpy="0 0 0" />
      <mass
        value="0.0731981137116207" />
      <inertia
        ixx="6.37411004153636E-05"
        ixy="0"
        ixz="1.1946615562955E-22"
        iyy="6.37411004153636E-05"
        iyz="1.1946615562955E-22"
        izz="5.56671654776875E-07" />
    </inertial>
    <visual>
      <origin
        xyz="0 0 0"
        rpy="0 0 0" />
      <geometry>
        <mesh
          filename="file://$(find snow_sim)/meshes_visual/wm3_steering_axis.STL" />
      </geometry>
      <material
        name="">
        <color
          rgba="0.698039215686274 0.698039215686274 0.698039215686274 1" />
      </material>
    </visual>
    <collision>
      <origin
        xyz="0 0 0"
        rpy="0 0 0" />
      <geometry>
        <mesh
          filename="file://$(find snow_sim)/meshes_collision/wm3_steering_axis.STL" />
      </geometry>
    </collision>
  </link>
  <joint
    name="wm3_base_to_steering_axis"
    type="revolute">
    <origin
      xyz="-0.0247487373415287 -0.0714177848998414 0"
      rpy="0 0 0" />
    <parent
      link="wm3_base" />
    <child
      link="wm3_steering_axis" />
    <axis
      xyz="0 0 -1" />
    <limit
      lower="-0.7854"
      upper="2.35619"
      effort="1000"
      velocity="0.5" />
    <dynamics 
      damping="1.00" 
      friction="1.00"/>
  </joint>
  <link
    name="wm3_arm">
    <inertial>
      <origin
        xyz="-2.77555756156289E-17 -0.0479626000129808 0.0356051741170328"
        rpy="0 0 0" />
      <mass
        value="0.227000002375456" />
      <inertia
        ixx="0.0002654967989859"
        ixy="-6.7762635780344E-20"
        ixz="1.86347248395946E-20"
        iyy="0.00010668622732319"
        iyz="2.88668700742115E-05"
        izz="0.00025047954689112" />
    </inertial>
    <visual>
      <origin
        xyz="0 0 0"
        rpy="0 0 0" />
      <geometry>
        <mesh
          filename="file://$(find snow_sim)/meshes_visual/wm3_arm.STL" />
      </geometry>
      <material
        name="">
        <color
          rgba="0.698039215686274 0.698039215686274 0.698039215686274 1" />
      </material>
    </visual>
    <collision>
      <origin
        xyz="0 0 0"
        rpy="0 0 0" />
      <geometry>
        <mesh
          filename="file://$(find snow_sim)/meshes_collision/wm3_arm.STL" />
      </geometry>
    </collision>
  </link>
  <joint
    name="wm3_steering_axis_to_arm"
    type="fixed">
    <origin
      xyz="0 0 0"
      rpy="0 0 0" />
    <parent
      link="wm3_steering_axis" />
    <child
      link="wm3_arm" />
    <axis
      xyz="0 0 0" />
  </joint>
  <link
    name="wm3_wheel">
    <inertial>
      <origin
        xyz="-1.3878E-17 0 0.026187"
        rpy="0 0 0" />
      <mass
        value="0.18198" />
      <inertia
        ixx="8.4567E-05"
        ixy="1.2214E-22"
        ixz="-2.7105E-20"
        iyy="8.4567E-05"
        iyz="-1.0133E-21"
        izz="0.00015944" />
    </inertial>
    <visual>
      <origin
        xyz="0 0 0"
        rpy="0 0 0" />
      <geometry>
        <mesh
          filename="file://$(find snow_sim)/meshes_visual/wm2_wheel.STL" />
      </geometry>
      <material
        name="">
        <color
          rgba="0.69804 0.69804 0.69804 1" />
      </material>
    </visual>
    <collision>
      <origin
        xyz="0 0 0.0275"
        rpy="0 0 0" />
      <geometry>
        <cylinder length="0.012" radius="0.044"/>
      </geometry>
    </collision>
  </link>
  <joint
    name="wm3_arm_to_wheel"
    type="continuous">
    <origin
      xyz="0 -0.09115 0.03"
      rpy="1.5707963267949 0 0" />
    <parent
      link="wm3_arm" />
    <child
      link="wm3_wheel" />
    <axis
      xyz="0 0 -1" />
  </joint>
  <link
    name="wm4_base">
    <inertial>
      <origin
        xyz="-0.0546227553283528 0.00795370777004067 0.0265672262517407"
        rpy="0 0 0" />
      <mass
        value="0.10699000447605" />
      <inertia
        ixx="0.000107088332273698"
        ixy="1.18802505025781E-05"
        ixz="-9.32799649935107E-07"
        iyy="0.000107088332273698"
        iyz="9.32799649935107E-07"
        izz="0.000101581821488797" />
    </inertial>
    <visual>
      <origin
        xyz="0 0 0"
        rpy="0 0 0" />
      <geometry>
        <mesh
          filename="file://$(find snow_sim)/meshes_visual/wm4_base.STL" />
      </geometry>
      <material
        name="">
        <color
          rgba="0.698039215686274 0.698039215686274 0.698039215686274 1" />
      </material>
    </visual>
    <collision>
      <origin
        xyz="0 0 0"
        rpy="0 0 0" />
      <geometry>
        <mesh
          filename="file://$(find snow_sim)/meshes_collision/wm4_base.STL" />
      </geometry>
    </collision>
  </link>
  <joint
    name="base_link_to_wm4_base"
    type="fixed">
    <origin
      xyz="-0.0570988725808137 0.103767920139126 0.014"
      rpy="0 0 0" />
    <parent
      link="base_link" />
    <child
      link="wm4_base" />
    <axis
      xyz="0 0 0" />
  </joint>
  <link
    name="wm4_break_enc">
    <inertial>
      <origin
        xyz="0 0 0.02335"
        rpy="0 0 0" />
      <mass
        value="0.420699883079902" />
      <inertia
        ixx="0.000160598323950158"
        ixy="-1.35525271560688E-20"
        ixz="3.91510497556737E-37"
        iyy="0.000160598323950158"
        iyz="3.91510497556737E-37"
        izz="0.000168279953231961" />
    </inertial>
    <visual>
      <origin
        xyz="0 0 0"
        rpy="0 0 0" />
      <geometry>
        <mesh
          filename="file://$(find snow_sim)/meshes_visual/wm4_brake_enc.STL" />
      </geometry>
      <material
        name="">
        <color
          rgba="0.698039215686274 0.698039215686274 0.698039215686274 1" />
      </material>
    </visual>
    <collision>
      <origin
        xyz="0 0 0"
        rpy="0 0 0" />
      <geometry>
        <mesh
          filename="file://$(find snow_sim)/meshes_collision/wm4_break_enc.STL" />
      </geometry>
    </collision>
  </link>
  <joint
    name="wm4_base_to_break_enc"
    type="fixed">
    <origin
      xyz="-0.0714177848998412 0.0247487373415291 0.058"
      rpy="0 0 0" />
    <parent
      link="wm4_base" />
    <child
      link="wm4_break_enc" />
    <axis
      xyz="0 0 0" />
  </joint>
  <link
    name="wm4_steering_axis">
    <inertial>
      <origin
        xyz="0 5.55111512312578E-17 0.051"
        rpy="0 0 0" />
      <mass
        value="0.0731981137116207" />
      <inertia
        ixx="6.37411004153636E-05"
        ixy="0"
        ixz="3.05315330573938E-37"
        iyy="6.37411004153636E-05"
        iyz="-4.3552003288063E-39"
        izz="5.56671654776874E-07" />
    </inertial>
    <visual>
      <origin
        xyz="0 0 0"
        rpy="0 0 0" />
      <geometry>
        <mesh
          filename="file://$(find snow_sim)/meshes_visual/wm4_steering_axis.STL" />
      </geometry>
      <material
        name="">
        <color
          rgba="0.698039215686274 0.698039215686274 0.698039215686274 1" />
      </material>
    </visual>
    <collision>
      <origin
        xyz="0 0 0"
        rpy="0 0 0" />
      <geometry>
        <mesh
          filename="file://$(find snow_sim)/meshes_collision/wm4_steering_axis.STL" />
      </geometry>
    </collision>
  </link>
  <joint
    name="wm4_base_to_steering_axis"
    type="revolute">
    <origin
      xyz="-0.0714177848998413 0.0247487373415291 0"
      rpy="0 0 0" />
    <parent
      link="wm4_base" />
    <child
      link="wm4_steering_axis" />
    <axis
      xyz="0 0 1" />
    <limit
      lower="-0.7854"
      upper="2.3562"
      effort="1000"
      velocity="0.5" />
    <dynamics 
      damping="1.00" 
      friction="1.00"/>
  </joint>
  <link
    name="wm4_arm">
    <inertial>
      <origin
        xyz="0 0.0479626000129808 0.0356051741170328"
        rpy="0 0 0" />
      <mass
        value="0.227000002375456" />
      <inertia
        ixx="0.0002654967989859"
        ixy="7.45388993583784E-20"
        ixz="8.470329472543E-21"
        iyy="0.00010668622732319"
        iyz="-2.88668700742115E-05"
        izz="0.000250479546891119" />
    </inertial>
    <visual>
      <origin
        xyz="0 0 0"
        rpy="0 0 0" />
      <geometry>
        <mesh
          filename="file://$(find snow_sim)/meshes_visual/wm4_arm.STL" />
      </geometry>
      <material
        name="">
        <color
          rgba="0.698039215686274 0.698039215686274 0.698039215686274 1" />
      </material>
    </visual>
    <collision>
      <origin
        xyz="0 0 0"
        rpy="0 0 0" />
      <geometry>
        <mesh
          filename="file://$(find snow_sim)/meshes_collision/wm4_arm.STL" />
      </geometry>
    </collision>
  </link>
  <joint
    name="wm4_steering_axis_to_arm"
    type="fixed">
    <origin
      xyz="0 0 0"
      rpy="0 0 0" />
    <parent
      link="wm4_steering_axis" />
    <child
      link="wm4_arm" />
    <axis
      xyz="0 0 0" />
  </joint>
  <link
    name="wm4_wheel">
    <inertial>
      <origin
        xyz="5.5511E-17 0 -0.026187"
        rpy="0 0 0" />
      <mass
        value="0.18198" />
      <inertia
        ixx="8.4567E-05"
        ixy="1.3277E-21"
        ixz="-1.6941E-20"
        iyy="8.4567E-05"
        iyz="6.6124E-22"
        izz="0.00015944" />
    </inertial>
    <visual>
      <origin
        xyz="0 0 0"
        rpy="0 0 0" />
      <geometry>
        <mesh
          filename="file://$(find snow_sim)/meshes_visual/wm4_wheel.STL" />
      </geometry>
      <material
        name="">
        <color
          rgba="0.69804 0.69804 0.69804 1" />
      </material>
    </visual>
    <collision>
      <origin
        xyz="0 0 -0.0275"
        rpy="0 3.14159265358979 0" />
      <geometry>
        <cylinder length="0.012" radius="0.044"/>
      </geometry>
    </collision>
  </link>
  <joint
    name="wm4_arm_to_wheel"
    type="continuous">
    <origin
      xyz="0 0.09115 0.03"
      rpy="1.5707963267949 0 0" />
    <parent
      link="wm4_arm" />
    <child
      link="wm4_wheel" />
    <axis
      xyz="0 0 -1" />
  </joint>









  <gazebo reference="wm1_wheel">
    <mu1 value="200.0"/>
    <mu2 value="100.0"/>
    <kp value="1000000.0" />
    <kd value="1.0" />
  </gazebo>
  <gazebo reference="wm2_wheel">
    <mu1 value="200.0"/>
    <mu2 value="100.0"/>
    <kp value="1000000.0" />
    <kd value="1.0" />
  </gazebo>
  <gazebo reference="wm3_wheel">
    <mu1 value="200.0"/>
    <mu2 value="100.0"/>
    <kp value="1000000.0" />
    <kd value="1.0" />
  </gazebo>
  <gazebo reference="wm4_wheel">
    <mu1 value="200.0"/>
    <mu2 value="100.0"/>
    <kp value="1000000.0" />
    <kd value="1.0" />
  </gazebo>












  <ros2_control name="GazeboSystem" type="system">
    <hardware>
      <plugin>gazebo_ros2_control/GazeboSystem</plugin>
    </hardware>

    <joint name="wm1_base_to_steering_axis">
      <command_interface name="effort">
        <param name="min">-1000</param>
        <param name="max">1000</param>
      </command_interface>
      <state_interface name="position">
        <param name="initial_value">0.0</param>
      </state_interface>
      <state_interface name="velocity"/>
      <state_interface name="effort"/>
    </joint>

    <joint name="wm1_arm_to_wheel">
      <command_interface name="effort">
        <param name="min">-1000</param>
        <param name="max">1000</param>
      </command_interface>
      <state_interface name="position">
        <param name="initial_value">0.0</param>
      </state_interface>
      <state_interface name="velocity"/>
      <state_interface name="effort"/>
    </joint>

    <joint name="wm2_base_to_steering_axis">
      <command_interface name="effort">
        <param name="min">-1000</param>
        <param name="max">1000</param>
      </command_interface>
      <state_interface name="position">
        <param name="initial_value">0.0</param>
      </state_interface>
      <state_interface name="velocity"/>
      <state_interface name="effort"/>
    </joint>

    <joint name="wm2_arm_to_wheel">
      <command_interface name="effort">
        <param name="min">-1000</param>
        <param name="max">1000</param>
      </command_interface>
      <state_interface name="position">
        <param name="initial_value">0.0</param>
      </state_interface>
      <state_interface name="velocity"/>
      <state_interface name="effort"/>
    </joint>

    <joint name="wm3_base_to_steering_axis">
      <command_interface name="effort">
        <param name="min">-1000</param>
        <param name="max">1000</param>
      </command_interface>
      <state_interface name="position">
        <param name="initial_value">0.0</param>
      </state_interface>
      <state_interface name="velocity"/>
      <state_interface name="effort"/>
    </joint>

    <joint name="wm3_arm_to_wheel">
      <command_interface name="effort">
        <param name="min">-1000</param>
        <param name="max">1000</param>
      </command_interface>
      <state_interface name="position">
        <param name="initial_value">0.0</param>
      </state_interface>
      <state_interface name="velocity"/>
      <state_interface name="effort"/>
    </joint>

    <joint name="wm4_base_to_steering_axis">
      <command_interface name="effort">
        <param name="min">-1000</param>
        <param name="max">1000</param>
      </command_interface>
      <state_interface name="position">
        <param name="initial_value">0.0</param>
      </state_interface>
      <state_interface name="velocity"/>
      <state_interface name="effort"/>
    </joint>

    <joint name="wm4_arm_to_wheel">
      <command_interface name="effort">
        <param name="min">-1000</param>
        <param name="max">1000</param>
      </command_interface>
      <state_interface name="position">
        <param name="initial_value">0.0</param>
      </state_interface>
      <state_interface name="velocity"/>
      <state_interface name="effort"/>
    </joint>

  </ros2_control>

  <gazebo>
    <plugin filename="libgazebo_ros2_control.so" name="gazebo_ros2_control">
      <parameters>$(find snow_sim)/config/snow_v3.yaml</parameters>
    </plugin>
  </gazebo>

</robot>
