<?xml version="1.0" encoding="utf-8"?>
<!-- This URDF was automatically created by SolidWorks to URDF Exporter! Originally created by Stephen Brawner (brawner@gmail.com) 
     Commit Version: 1.6.0-4-g7f85cfe  Build Version: 1.6.7995.38578
     For more information, please see http://wiki.ros.org/sw_urdf_exporter -->
<robot
  name="snowbot_simple">
  <link
    name="base_link">
    <inertial>
      <origin
        xyz="-1.04083408558608E-17 1.38777878078145E-17 0.042"
        rpy="0 0 0" />
      <mass
        value="2.282808" />
      <inertia
        ixx="0.013361138208"
        ixy="6.93889390390723E-18"
        ixz="1.19038859495907E-19"
        iyy="0.013361138208"
        iyz="2.5005758406602E-19"
        izz="0.025300928752" />
    </inertial>
    <visual>
      <origin
        xyz="0 0 0"
        rpy="0 0 0" />
      <geometry>
        <mesh
          filename="file://$(find urdf_tutorial)/meshes/base_link.STL" />
      </geometry>
      <material
        name="">
        <color
          rgba="0.792156862745098 0.819607843137255 0.933333333333333 1" />
      </material>
    </visual>
    <collision>
      <origin
        xyz="0 0 0"
        rpy="0 0 0" />
      <geometry>
        <mesh
          filename="file://$(find urdf_tutorial)/meshes/base_link.STL" />
      </geometry>
    </collision>
  </link>
  <link
    name="wm1">
    <inertial>
      <origin
        xyz="0.0427351379564552 5.53897205879395E-15 -0.0229933385881073"
        rpy="0 0 0" />
      <mass
        value="0.241464642114672" />
      <inertia
        ixx="9.02315680937691E-05"
        ixy="1.35756536294494E-20"
        ixz="-9.69357557072525E-08"
        iyy="0.000268550530469722"
        iyz="-5.03410848927965E-21"
        izz="0.000273896352939588" />
    </inertial>
    <visual>
      <origin
        xyz="0 0 0"
        rpy="0 0 0" />
      <geometry>
        <mesh
          filename="file://$(find urdf_tutorial)/meshes/wm1.STL" />
      </geometry>
      <material
        name="">
        <color
          rgba="0.792156862745098 0.819607843137255 0.933333333333333 1" />
      </material>
    </visual>
    <collision>
      <origin
        xyz="0 0 0"
        rpy="0 0 0" />
      <geometry>
        <mesh
          filename="file://$(find urdf_tutorial)/meshes/wm1.STL" />
      </geometry>
    </collision>
  </link>
  <joint
    name="base_to_wm1"
    type="revolute">
    <origin
      xyz="-0.128693434175956 -0.128693434175948 0.065"
      rpy="0 0 -2.35619449019234" />
    <parent
      link="base_link" />
    <child
      link="wm1" />
    <axis
      xyz="0 0 1" />
    <limit
      lower="-1.57"
      upper="1.57"
      effort="1000"
      velocity="0.5" />
  </joint>
  <link
    name="wm1_wheel">
    <inertial>
      <origin
        xyz="0 0 0.004"
        rpy="0 0 0" />
      <mass
        value="0.0486569870187987" />
      <inertia
        ixx="2.38094856478655E-05"
        ixy="3.58224350609632E-21"
        ixz="8.02597043407471E-23"
        iyy="2.38094856478655E-05"
        iyz="-6.21655242886776E-23"
        izz="4.70999634341972E-05" />
    </inertial>
    <visual>
      <origin
        xyz="0 0 0"
        rpy="0 0 0" />
      <geometry>
        <mesh
          filename="file://$(find urdf_tutorial)/meshes/wm1_wheel.STL" />
      </geometry>
      <material
        name="">
        <color
          rgba="0.792156862745098 0.819607843137255 0.933333333333333 1" />
      </material>
    </visual>
    <collision>
      <origin
        xyz="0 0 0"
        rpy="0 0 0" />
      <geometry>
        <mesh
          filename="file://$(find urdf_tutorial)/meshes/wm1_wheel.STL" />
      </geometry>
    </collision>
  </link>
  <joint
    name="wm1_to_wheel"
    type="continuous">
    <origin
      xyz="0.111 0 -0.021"
      rpy="0 1.5707963267949 0" />
    <parent
      link="wm1" />
    <child
      link="wm1_wheel" />
    <axis
      xyz="0 0 -1" />
  </joint>
  <link
    name="wm2">
    <inertial>
      <origin
        xyz="0.0427351379564557 0 -0.0229933385881074"
        rpy="0 0 0" />
      <mass
        value="0.241464642114672" />
      <inertia
        ixx="9.02315680937691E-05"
        ixy="3.89510148979579E-21"
        ixz="-9.69357557072448E-08"
        iyy="0.000268550530469722"
        iyz="-2.39303935433597E-21"
        izz="0.000273896352939588" />
    </inertial>
    <visual>
      <origin
        xyz="0 0 0"
        rpy="0 0 0" />
      <geometry>
        <mesh
          filename="file://$(find urdf_tutorial)/meshes/wm2.STL" />
      </geometry>
      <material
        name="">
        <color
          rgba="0.792156862745098 0.819607843137255 0.933333333333333 1" />
      </material>
    </visual>
    <collision>
      <origin
        xyz="0 0 0"
        rpy="0 0 0" />
      <geometry>
        <mesh
          filename="file://$(find urdf_tutorial)/meshes/wm2.STL" />
      </geometry>
    </collision>
  </link>
  <joint
    name="base_to_wm2"
    type="revolute">
    <origin
      xyz="0.128693434175952 -0.128693434175952 0.065"
      rpy="0 0 -0.785398163397449" />
    <parent
      link="base_link" />
    <child
      link="wm2" />
    <axis
      xyz="0 0 1" />
    <limit
      lower="-1.57"
      upper="1.57"
      effort="1000"
      velocity="0.5" />
  </joint>
  <link
    name="wm2_wheel">
    <inertial>
      <origin
        xyz="0 0 0.004"
        rpy="0 0 0" />
      <mass
        value="0.0486569870187987" />
      <inertia
        ixx="2.38094856478655E-05"
        ixy="-1.83876735633121E-21"
        ixz="-2.84839821544422E-23"
        iyy="2.38094856478655E-05"
        iyz="1.61582460127306E-22"
        izz="4.70999634341972E-05" />
    </inertial>
    <visual>
      <origin
        xyz="0 0 0"
        rpy="0 0 0" />
      <geometry>
        <mesh
          filename="file://$(find urdf_tutorial)/meshes/wm2_wheel.STL" />
      </geometry>
      <material
        name="">
        <color
          rgba="0.792156862745098 0.819607843137255 0.933333333333333 1" />
      </material>
    </visual>
    <collision>
      <origin
        xyz="0 0 0"
        rpy="0 0 0" />
      <geometry>
        <mesh
          filename="file://$(find urdf_tutorial)/meshes/wm2_wheel.STL" />
      </geometry>
    </collision>
  </link>
  <joint
    name="wm2_to_wheel"
    type="continuous">
    <origin
      xyz="0.111 0 -0.021"
      rpy="0 1.5707963267949 0" />
    <parent
      link="wm2" />
    <child
      link="wm2_wheel" />
    <axis
      xyz="0 0 -1" />
  </joint>
  <link
    name="wm3">
    <inertial>
      <origin
        xyz="0.0427351379564557 -4.59701721133854E-17 -0.0229933385881072"
        rpy="0 0 0" />
      <mass
        value="0.241464642114672" />
      <inertia
        ixx="9.02315680937692E-05"
        ixy="4.14122525352501E-20"
        ixz="-9.69357557075524E-08"
        iyy="0.000268550530469722"
        iyz="5.05727055293542E-21"
        izz="0.000273896352939588" />
    </inertial>
    <visual>
      <origin
        xyz="0 0 0"
        rpy="0 0 0" />
      <geometry>
        <mesh
          filename="file://$(find urdf_tutorial)/meshes/wm3.STL" />
      </geometry>
      <material
        name="">
        <color
          rgba="0.792156862745098 0.819607843137255 0.933333333333333 1" />
      </material>
    </visual>
    <collision>
      <origin
        xyz="0 0 0"
        rpy="0 0 0" />
      <geometry>
        <mesh
          filename="file://$(find urdf_tutorial)/meshes/wm3.STL" />
      </geometry>
    </collision>
  </link>
  <joint
    name="base_to_wm3"
    type="revolute">
    <origin
      xyz="0.128693434175952 0.128693434175952 0.0649999999999999"
      rpy="0 0 0.785398163397448" />
    <parent
      link="base_link" />
    <child
      link="wm3" />
    <axis
      xyz="0 0 1" />
    <limit
      lower="-1.57"
      upper="1.57"
      effort="1000"
      velocity="0.5" />
  </joint>
  <link
    name="wm3_wheel">
    <inertial>
      <origin
        xyz="-6.93889390390723E-18 8.67361737988404E-19 0.004"
        rpy="0 0 0" />
      <mass
        value="0.0486569870187987" />
      <inertia
        ixx="2.38094856478655E-05"
        ixy="-2.95226275157593E-21"
        ixz="2.22450107076406E-22"
        iyy="2.38094856478655E-05"
        iyz="-1.48161194119155E-22"
        izz="4.70999634341972E-05" />
    </inertial>
    <visual>
      <origin
        xyz="0 0 0"
        rpy="0 0 0" />
      <geometry>
        <mesh
          filename="file://$(find urdf_tutorial)/meshes/wm3_wheel.STL" />
      </geometry>
      <material
        name="">
        <color
          rgba="0.792156862745098 0.819607843137255 0.933333333333333 1" />
      </material>
    </visual>
    <collision>
      <origin
        xyz="0 0 0"
        rpy="0 0 0" />
      <geometry>
        <mesh
          filename="file://$(find urdf_tutorial)/meshes/wm3_wheel.STL" />
      </geometry>
    </collision>
  </link>
  <joint
    name="wm3_to_wheel"
    type="continuous">
    <origin
      xyz="0.111 0 -0.0209999999999998"
      rpy="0 1.5707963267949 0" />
    <parent
      link="wm3" />
    <child
      link="wm3_wheel" />
    <axis
      xyz="0 0 -1" />
  </joint>
  <link
    name="wm4">
    <inertial>
      <origin
        xyz="0.0427351379564548 -2.71310751642773E-15 -0.0229933385881074"
        rpy="0 0 0" />
      <mass
        value="0.241464642114672" />
      <inertia
        ixx="9.02315680937691E-05"
        ixy="-1.49888296786816E-20"
        ixz="-9.69357557071191E-08"
        iyy="0.000268550530469722"
        iyz="3.09796700129124E-21"
        izz="0.000273896352939588" />
    </inertial>
    <visual>
      <origin
        xyz="0 0 0"
        rpy="0 0 0" />
      <geometry>
        <mesh
          filename="file://$(find urdf_tutorial)/meshes/wm4.STL" />
      </geometry>
      <material
        name="">
        <color
          rgba="0.792156862745098 0.819607843137255 0.933333333333333 1" />
      </material>
    </visual>
    <collision>
      <origin
        xyz="0 0 0"
        rpy="0 0 0" />
      <geometry>
        <mesh
          filename="file://$(find urdf_tutorial)/meshes/wm4.STL" />
      </geometry>
    </collision>
  </link>
  <joint
    name="base_to_wm4"
    type="revolute">
    <origin
      xyz="-0.128693434175954 0.12869343417595 0.065"
      rpy="0 0 2.35619449019234" />
    <parent
      link="base_link" />
    <child
      link="wm4" />
    <axis
      xyz="0 0 1" />
    <limit
      lower="-1.57"
      upper="1.57"
      effort="1000"
      velocity="0.5" />
  </joint>
  <link
    name="wm4_wheel">
    <inertial>
      <origin
        xyz="6.93889390390723E-18 6.93889390390723E-18 0.004"
        rpy="0 0 0" />
      <mass
        value="0.0486569870187988" />
      <inertia
        ixx="2.38094856478655E-05"
        ixy="-1.14172982681985E-21"
        ixz="1.84641454246241E-20"
        iyy="2.38094856478655E-05"
        iyz="9.21337263811285E-21"
        izz="4.70999634341972E-05" />
    </inertial>
    <visual>
      <origin
        xyz="0 0 0"
        rpy="0 0 0" />
      <geometry>
        <mesh
          filename="file://$(find urdf_tutorial)/meshes/wm4_wheel.STL" />
      </geometry>
      <material
        name="">
        <color
          rgba="0.792156862745098 0.819607843137255 0.933333333333333 1" />
      </material>
    </visual>
    <collision>
      <origin
        xyz="0 0 0"
        rpy="0 0 0" />
      <geometry>
        <mesh
          filename="file://$(find urdf_tutorial)/meshes/wm4_wheel.STL" />
      </geometry>
    </collision>
  </link>
  <joint
    name="wm4_to_wheel"
    type="continuous">
    <origin
      xyz="0.110999999999999 0 -0.0210000000000001"
      rpy="0 1.5707963267949 0" />
    <parent
      link="wm4" />
    <child
      link="wm4_wheel" />
    <axis
      xyz="0 0 -1" />
  </joint>
</robot>
