<?xml version="1.0" encoding="utf-8"?>
<!-- This URDF was automatically created by SolidWorks to URDF Exporter! Originally created by Stephen Brawner (brawner@gmail.com) 
     Commit Version: 1.6.0-4-g7f85cfe  Build Version: 1.6.7995.38578
     For more information, please see http://wiki.ros.org/sw_urdf_exporter -->
<robot
  name="origins">
  <link
    name="base_link">
    <inertial>
      <origin
        xyz="0 0 0.043197"
        rpy="0 0 0" />
      <mass
        value="0.404" />
        <!-- value="0.404" -->
      <inertia
        ixx="0.0016645"
        ixy="0"
        ixz="0"
        iyy="0.0016645"
        iyz="0"
        izz="0.0031794" />
    </inertial>
    <visual>
      <origin
        xyz="0 0 0"
        rpy="0 0 0" />
      <geometry>
        <mesh
          filename="file://$(find urdf_tutorial)/meshes/base_link.STL" />
      </geometry>
      <material
        name="">
        <color
          rgba="0.69804 0.69804 0.69804 1" />
      </material>
    </visual>
    <collision>
      <origin
        xyz="0 0 0"
        rpy="0 0 0" />
      <geometry>
        <mesh
          filename="file://$(find urdf_tutorial)/meshes/base_link.STL" />
      </geometry>
    </collision>
  </link>
  <link
    name="wm1_base">
    <inertial>
      <origin
        xyz="0.0079537 0.054623 0.026567"
        rpy="0 0 0" />
      <mass
        value="0.10699" />
      <inertia
        ixx="0.00010709"
        ixy="-1.188E-05"
        ixz="0"
        iyy="0.00010709"
        iyz="0"
        izz="0.00010158" />
    </inertial>
    <visual>
      <origin
        xyz="0 0 0"
        rpy="0 0 0" />
      <geometry>
        <mesh
          filename="file://$(find urdf_tutorial)/meshes/wm1_base.STL" />
      </geometry>
      <material
        name="">
        <color
          rgba="0.69804 0.69804 0.69804 1" />
      </material>
    </visual>
    <collision>
      <origin
        xyz="0 0 0"
        rpy="0 0 0" />
      <geometry>
        <mesh
          filename="file://$(find urdf_tutorial)/meshes/wm1_base.STL" />
      </geometry>
    </collision>
  </link>
  <joint
    name="base_link_to_wm1_base"
    type="fixed">
    <origin
      xyz="0.103767920139126 0.0570988725808139 0.014"
      rpy="0 0 0" />
    <parent
      link="base_link" />
    <child
      link="wm1_base" />
    <axis
      xyz="0 0 0" />
  </joint>
  <link
    name="wm1_break_enc">
    <inertial>
      <origin
        xyz="0 0 0.02335"
        rpy="0 0 0" />
      <mass
        value="0.4207" />
      <inertia
        ixx="0.0001606"
        ixy="0"
        ixz="0"
        iyy="0.0001606"
        iyz="0"
        izz="0.00016828" />
    </inertial>
    <visual>
      <origin
        xyz="0 0 0"
        rpy="0 0 0" />
      <geometry>
        <mesh
          filename="file://$(find urdf_tutorial)/meshes/wm1_break_enc.STL" />
      </geometry>
      <material
        name="">
        <color
          rgba="0.69804 0.69804 0.69804 1" />
      </material>
    </visual>
    <collision>
      <origin
        xyz="0 0 0"
        rpy="0 0 0" />
      <geometry>
        <mesh
          filename="file://$(find urdf_tutorial)/meshes/wm1_break_enc.STL" />
      </geometry>
    </collision>
  </link>
  <joint
    name="wm1_base_to_break_enc"
    type="fixed">
    <origin
      xyz="0.024749 0.071418 0.058"
      rpy="0 0 0" />
    <parent
      link="wm1_base" />
    <child
      link="wm1_break_enc" />
    <axis
      xyz="0 0 0" />
  </joint>
  <link
    name="wm1_steering_axis">
    <inertial>
      <origin
        xyz="0 0 0.051"
        rpy="0 0 0" />
      <mass
        value="0.077" />
      <inertia
        ixx="6.7067E-05"
        ixy="0"
        ixz="0"
        iyy="6.7067E-05"
        iyz="0"
        izz="0" />
    </inertial>
    <visual>
      <origin
        xyz="0 0 0"
        rpy="0 0 0" />
      <geometry>
        <mesh
          filename="file://$(find urdf_tutorial)/meshes/wm1_steering_axis.STL" />
      </geometry>
      <material
        name="">
        <color
          rgba="0.69804 0.69804 0.69804 1" />
      </material>
    </visual>
    <collision>
      <origin
        xyz="0 0 0"
        rpy="0 0 0" />
      <geometry>
        <mesh
          filename="file://$(find urdf_tutorial)/meshes/wm1_steering_axis.STL" />
      </geometry>
    </collision>
  </link>
  <joint
    name="wm1_base_to_steering_axis"
    type="revolute">
    <origin
      xyz="0.024749 0.071418 0"
      rpy="0 0 0" />
    <parent
      link="wm1_base" />
    <child
      link="wm1_steering_axis" />
    <axis
      xyz="0 0 1" />
    <limit
      lower="-2.3562"
      upper="0.7854"
      effort="1000"
      velocity="1" />
  </joint>
  <link
    name="wm1_arm">
    <inertial>
      <origin
        xyz="0 0.045241 0.035605"
        rpy="0 0 0" />
      <mass
        value="0.227" />
      <inertia
        ixx="0.00026595"
        ixy="0"
        ixz="0"
        iyy="0.00010669"
        iyz="-2.8894E-05"
        izz="0.00025093" />
    </inertial>
    <visual>
      <origin
        xyz="0 0 0"
        rpy="0 0 0" />
      <geometry>
        <mesh
          filename="file://$(find urdf_tutorial)/meshes/wm1_arm.STL" />
      </geometry>
      <material
        name="">
        <color
          rgba="0.69804 0.69804 0.69804 1" />
      </material>
    </visual>
    <collision>
      <origin
        xyz="0 0 0"
        rpy="0 0 0" />
      <geometry>
        <mesh
          filename="file://$(find urdf_tutorial)/meshes/wm1_arm.STL" />
      </geometry>
    </collision>
  </link>
  <joint
    name="wm1_steering_axis_to_arm"
    type="fixed">
    <origin
      xyz="0 0 0"
      rpy="0 0 0" />
    <parent
      link="wm1_steering_axis" />
    <child
      link="wm1_arm" />
    <axis
      xyz="0 0 0" />
  </joint>
  <link
    name="wm1_wheel">
    <inertial>
      <origin
        xyz="0 0 0.026185"
        rpy="0 0 0" />
      <mass
        value="0.182" />
        <!-- value="0.182" -->
      <inertia
        ixx="8.4576E-05"
        ixy="0"
        ixz="0"
        iyy="8.4576E-05"
        iyz="0"
        izz="0.00015944" />
    </inertial>
    <visual>
      <origin
        xyz="0 0 0"
        rpy="0 0 0" />
      <geometry>
        <mesh
          filename="file://$(find urdf_tutorial)/meshes/wm1_wheel.STL" />
      </geometry>
      <material
        name="">
        <color
          rgba="0.69804 0.69804 0.69804 1" />
      </material>
    </visual>
    <collision>
      <origin
        xyz="0 0 0"
        rpy="0 0 0" />
      <geometry>
        <mesh
          filename="file://$(find urdf_tutorial)/meshes/wm1_wheel.STL" />
      </geometry>
    </collision>
  </link>
  <joint
    name="wm1_arm_to_wheel"
    type="continuous">
    <origin
      xyz="0 0.0884500000000001 0.03"
      rpy="0 0 0" />
    <parent
      link="wm1_arm" />
    <child
      link="wm1_wheel" />
    <axis
      xyz="0 0 -1" />
  </joint>
  <link
    name="wm2_base">
    <inertial>
      <origin
        xyz="0.054623 -0.0079537 0.026567"
        rpy="0 0 0" />
      <mass
        value="0.10699" />
      <inertia
        ixx="0.00010709"
        ixy="1.188E-05"
        ixz="0"
        iyy="0.00010709"
        iyz="0"
        izz="0.00010158" />
    </inertial>
    <visual>
      <origin
        xyz="0 0 0"
        rpy="0 0 0" />
      <geometry>
        <mesh
          filename="file://$(find urdf_tutorial)/meshes/wm2_base.STL" />
      </geometry>
      <material
        name="">
        <color
          rgba="0.69804 0.69804 0.69804 1" />
      </material>
    </visual>
    <collision>
      <origin
        xyz="0 0 0"
        rpy="0 0 0" />
      <geometry>
        <mesh
          filename="file://$(find urdf_tutorial)/meshes/wm2_base.STL" />
      </geometry>
    </collision>
  </link>
  <joint
    name="base_link_to_wm2_base"
    type="fixed">
    <origin
      xyz="0.0570988725808137 -0.103767920139126 0.014"
      rpy="0 0 0" />
    <parent
      link="base_link" />
    <child
      link="wm2_base" />
    <axis
      xyz="0 0 0" />
  </joint>
  <link
    name="wm2_break_enc">
    <inertial>
      <origin
        xyz="0 0 0.02335"
        rpy="0 0 0" />
      <mass
        value="0.4207" />
      <inertia
        ixx="0.0001606"
        ixy="0"
        ixz="0"
        iyy="0.0001606"
        iyz="0"
        izz="0.00016828" />
    </inertial>
    <visual>
      <origin
        xyz="0 0 0"
        rpy="0 0 0" />
      <geometry>
        <mesh
          filename="file://$(find urdf_tutorial)/meshes/wm2_break_enc.STL" />
      </geometry>
      <material
        name="">
        <color
          rgba="0.69804 0.69804 0.69804 1" />
      </material>
    </visual>
    <collision>
      <origin
        xyz="0 0 0"
        rpy="0 0 0" />
      <geometry>
        <mesh
          filename="file://$(find urdf_tutorial)/meshes/wm2_break_enc.STL" />
      </geometry>
    </collision>
  </link>
  <joint
    name="wm2_base_to_break_enc"
    type="fixed">
    <origin
      xyz="0.071418 -0.024749 0.058"
      rpy="0 0 0" />
    <parent
      link="wm2_base" />
    <child
      link="wm2_break_enc" />
    <axis
      xyz="0 0 0" />
  </joint>
  <link
    name="wm2_steering_axis">
    <inertial>
      <origin
        xyz="0 0 0.051"
        rpy="0 0 0" />
      <mass
        value="0.077" />
      <inertia
        ixx="6.7067E-05"
        ixy="0"
        ixz="0"
        iyy="6.7067E-05"
        iyz="0"
        izz="0" />
    </inertial>
    <visual>
      <origin
        xyz="0 0 0"
        rpy="0 0 0" />
      <geometry>
        <mesh
          filename="file://$(find urdf_tutorial)/meshes/wm2_steering_axis.STL" />
      </geometry>
      <material
        name="">
        <color
          rgba="0.69804 0.69804 0.69804 1" />
      </material>
    </visual>
    <collision>
      <origin
        xyz="0 0 0"
        rpy="0 0 0" />
      <geometry>
        <mesh
          filename="file://$(find urdf_tutorial)/meshes/wm2_steering_axis.STL" />
      </geometry>
    </collision>
  </link>
  <joint
    name="wm2_base_to_steering_axis"
    type="revolute">
    <origin
      xyz="0.071418 -0.024749 0"
      rpy="0 0 0" />
    <parent
      link="wm2_base" />
    <child
      link="wm2_steering_axis" />
    <axis
      xyz="0 0 1" />
    <limit
      lower="-0.7854"
      upper="2.3562"
      effort="1000"
      velocity="1" />
  </joint>
  <link
    name="wm2_arm">
    <inertial>
      <origin
        xyz="0 -0.045241 0.035605"
        rpy="0 0 0" />
      <mass
        value="0.227" />
      <inertia
        ixx="0.00026595"
        ixy="0"
        ixz="0"
        iyy="0.00010669"
        iyz="2.8894E-05"
        izz="0.00025093" />
    </inertial>
    <visual>
      <origin
        xyz="0 0 0"
        rpy="0 0 0" />
      <geometry>
        <mesh
          filename="file://$(find urdf_tutorial)/meshes/wm2_arm.STL" />
      </geometry>
      <material
        name="">
        <color
          rgba="0.69804 0.69804 0.69804 1" />
      </material>
    </visual>
    <collision>
      <origin
        xyz="0 0 0"
        rpy="0 0 0" />
      <geometry>
        <mesh
          filename="file://$(find urdf_tutorial)/meshes/wm2_arm.STL" />
      </geometry>
    </collision>
  </link>
  <joint
    name="wm2_steering_axis_to_arm"
    type="fixed">
    <origin
      xyz="0 0 0"
      rpy="0 0 0" />
    <parent
      link="wm2_steering_axis" />
    <child
      link="wm2_arm" />
    <axis
      xyz="0 0 0" />
  </joint>
  <link
    name="wm2_wheel">
    <inertial>
      <origin
        xyz="0 0 0.026185"
        rpy="0 0 0" />
      <mass
        value="0.182" />
      <inertia
        ixx="8.4576E-05"
        ixy="0"
        ixz="0"
        iyy="8.4576E-05"
        iyz="0"
        izz="0.00015944" />
    </inertial>
    <visual>
      <origin
        xyz="0 0 0"
        rpy="0 0 0" />
      <geometry>
        <mesh
          filename="file://$(find urdf_tutorial)/meshes/wm2_wheel.STL" />
      </geometry>
      <material
        name="">
        <color
          rgba="0.69804 0.69804 0.69804 1" />
      </material>
    </visual>
    <collision>
      <origin
        xyz="0 0 0"
        rpy="0 0 0" />
      <geometry>
        <mesh
          filename="file://$(find urdf_tutorial)/meshes/wm2_wheel.STL" />
      </geometry>
    </collision>
  </link>
  <joint
    name="wm2_arm_to_wheel"
    type="continuous">
    <origin
      xyz="0 -0.0884499999999999 0.03"
      rpy="1.5707963267949 0 0" />
    <parent
      link="wm2_arm" />
    <child
      link="wm2_wheel" />
    <axis
      xyz="0 0 -1" />
  </joint>
  <link
    name="wm3_base">
    <inertial>
      <origin
        xyz="-0.0079537 -0.054623 0.026567"
        rpy="0 0 0" />
      <mass
        value="0.10699" />
      <inertia
        ixx="0.00010709"
        ixy="-1.188E-05"
        ixz="0"
        iyy="0.00010709"
        iyz="0"
        izz="0.00010158" />
    </inertial>
    <visual>
      <origin
        xyz="0 0 0"
        rpy="0 0 0" />
      <geometry>
        <mesh
          filename="file://$(find urdf_tutorial)/meshes/wm3_base.STL" />
      </geometry>
      <material
        name="">
        <color
          rgba="0.69804 0.69804 0.69804 1" />
      </material>
    </visual>
    <collision>
      <origin
        xyz="0 0 0"
        rpy="0 0 0" />
      <geometry>
        <mesh
          filename="file://$(find urdf_tutorial)/meshes/wm3_base.STL" />
      </geometry>
    </collision>
  </link>
  <joint
    name="base_link_to_wm3_base"
    type="fixed">
    <origin
      xyz="-0.103767920139127 -0.0570988725808137 0.014"
      rpy="0 0 0" />
    <parent
      link="base_link" />
    <child
      link="wm3_base" />
    <axis
      xyz="0 0 0" />
  </joint>
  <link
    name="wm3_break_enc">
    <inertial>
      <origin
        xyz="0 0 0.02335"
        rpy="0 0 0" />
      <mass
        value="0.4207" />
      <inertia
        ixx="0.0001606"
        ixy="0"
        ixz="0"
        iyy="0.0001606"
        iyz="0"
        izz="0.00016828" />
    </inertial>
    <visual>
      <origin
        xyz="0 0 0"
        rpy="0 0 0" />
      <geometry>
        <mesh
          filename="file://$(find urdf_tutorial)/meshes/wm3_break_enc.STL" />
      </geometry>
      <material
        name="">
        <color
          rgba="0.69804 0.69804 0.69804 1" />
      </material>
    </visual>
    <collision>
      <origin
        xyz="0 0 0"
        rpy="0 0 0" />
      <geometry>
        <mesh
          filename="file://$(find urdf_tutorial)/meshes/wm3_break_enc.STL" />
      </geometry>
    </collision>
  </link>
  <joint
    name="wm3_base_to_break_enc"
    type="fixed">
    <origin
      xyz="-0.0247487373415287 -0.0714177848998415 0.058"
      rpy="0 0 0" />
    <parent
      link="wm3_base" />
    <child
      link="wm3_break_enc" />
    <axis
      xyz="0 0 0" />
  </joint>
  <link
    name="wm3_steering_axis">
    <inertial>
      <origin
        xyz="0 0 0.051"
        rpy="0 0 0" />
      <mass
        value="0.077" />
      <inertia
        ixx="6.7067E-05"
        ixy="0"
        ixz="0"
        iyy="6.7067E-05"
        iyz="0"
        izz="0" />
    </inertial>
    <visual>
      <origin
        xyz="0 0 0"
        rpy="0 0 0" />
      <geometry>
        <mesh
          filename="file://$(find urdf_tutorial)/meshes/wm3_steering_axis.STL" />
      </geometry>
      <material
        name="">
        <color
          rgba="0.69804 0.69804 0.69804 1" />
      </material>
    </visual>
    <collision>
      <origin
        xyz="0 0 0"
        rpy="0 0 0" />
      <geometry>
        <mesh
          filename="file://$(find urdf_tutorial)/meshes/wm3_steering_axis.STL" />
      </geometry>
    </collision>
  </link>
  <joint
    name="wm3_base_to_steering_axis"
    type="revolute">
    <origin
      xyz="-0.024749 -0.071418 0"
      rpy="0 0 0" />
    <parent
      link="wm3_base" />
    <child
      link="wm3_steering_axis" />
    <axis
      xyz="0 0 1" />
    <limit
      lower="-2.3562"
      upper="0.7854"
      effort="1000"
      velocity="1" />
  </joint>
  <link
    name="wm3_arm">
    <inertial>
      <origin
        xyz="0 -0.045241 0.035605"
        rpy="0 0 0" />
      <mass
        value="0.227" />
      <inertia
        ixx="0.00026595"
        ixy="0"
        ixz="0"
        iyy="0.00010669"
        iyz="2.8894E-05"
        izz="0.00025093" />
    </inertial>
    <visual>
      <origin
        xyz="0 0 0"
        rpy="0 0 0" />
      <geometry>
        <mesh
          filename="file://$(find urdf_tutorial)/meshes/wm3_arm.STL" />
      </geometry>
      <material
        name="">
        <color
          rgba="0.69804 0.69804 0.69804 1" />
      </material>
    </visual>
    <collision>
      <origin
        xyz="0 0 0"
        rpy="0 0 0" />
      <geometry>
        <mesh
          filename="file://$(find urdf_tutorial)/meshes/wm3_arm.STL" />
      </geometry>
    </collision>
  </link>
  <joint
    name="wm3_steering_axis_to_arm"
    type="fixed">
    <origin
      xyz="0 0 0"
      rpy="0 0 0" />
    <parent
      link="wm3_steering_axis" />
    <child
      link="wm3_arm" />
    <axis
      xyz="0 0 0" />
  </joint>
  <link
    name="wm3_wheel">
    <inertial>
      <origin
        xyz="0 0 0.026185"
        rpy="0 0 0" />
      <mass
        value="0.182" />
      <inertia
        ixx="8.4576E-05"
        ixy="0"
        ixz="0"
        iyy="8.4576E-05"
        iyz="0"
        izz="0.00015944" />
    </inertial>
    <visual>
      <origin
        xyz="0 0 0"
        rpy="0 0 0" />
      <geometry>
        <mesh
          filename="file://$(find urdf_tutorial)/meshes/wm3_wheel.STL" />
      </geometry>
      <material
        name="">
        <color
          rgba="0.69804 0.69804 0.69804 1" />
      </material>
    </visual>
    <collision>
      <origin
        xyz="0 0 0"
        rpy="0 0 0" />
      <geometry>
        <mesh
          filename="file://$(find urdf_tutorial)/meshes/wm3_wheel.STL" />
      </geometry>
    </collision>
  </link>
  <joint
    name="wm3_arm_to_wheel"
    type="continuous">
    <origin
      xyz="0 -0.0884500000000001 0.03"
      rpy="1.5707963267949 0 0" />
    <parent
      link="wm3_arm" />
    <child
      link="wm3_wheel" />
    <axis
      xyz="0 0 -1" />
  </joint>
  <link
    name="wm4_base">
    <inertial>
      <origin
        xyz="-0.054623 0.0079537 0.026567"
        rpy="0 0 0" />
      <mass
        value="0.10699" />
      <inertia
        ixx="0.00010709"
        ixy="1.188E-05"
        ixz="0"
        iyy="0.00010709"
        iyz="0"
        izz="0.00010158" />
    </inertial>
    <visual>
      <origin
        xyz="0 0 0"
        rpy="0 0 0" />
      <geometry>
        <mesh
          filename="file://$(find urdf_tutorial)/meshes/wm4_base.STL" />
      </geometry>
      <material
        name="">
        <color
          rgba="0.69804 0.69804 0.69804 1" />
      </material>
    </visual>
    <collision>
      <origin
        xyz="0 0 0"
        rpy="0 0 0" />
      <geometry>
        <mesh
          filename="file://$(find urdf_tutorial)/meshes/wm4_base.STL" />
      </geometry>
    </collision>
  </link>
  <joint
    name="base_link_to_wm4_base"
    type="fixed">
    <origin
      xyz="-0.0570988725808137 0.103767920139126 0.014"
      rpy="0 0 0" />
    <parent
      link="base_link" />
    <child
      link="wm4_base" />
    <axis
      xyz="0 0 0" />
  </joint>
  <link
    name="wm4_break_enc">
    <inertial>
      <origin
        xyz="0 0 0.02335"
        rpy="0 0 0" />
      <mass
        value="0.4207" />
      <inertia
        ixx="0.0001606"
        ixy="0"
        ixz="0"
        iyy="0.0001606"
        iyz="0"
        izz="0.00016828" />
    </inertial>
    <visual>
      <origin
        xyz="0 0 0"
        rpy="0 0 0" />
      <geometry>
        <mesh
          filename="file://$(find urdf_tutorial)/meshes/wm4_break_enc.STL" />
      </geometry>
      <material
        name="">
        <color
          rgba="0.69804 0.69804 0.69804 1" />
      </material>
    </visual>
    <collision>
      <origin
        xyz="0 0 0"
        rpy="0 0 0" />
      <geometry>
        <mesh
          filename="file://$(find urdf_tutorial)/meshes/wm4_break_enc.STL" />
      </geometry>
    </collision>
  </link>
  <joint
    name="wm4_base_to_break_enc"
    type="fixed">
    <origin
      xyz="-0.0714177848998412 0.0247487373415291 0.058"
      rpy="0 0 0" />
    <parent
      link="wm4_base" />
    <child
      link="wm4_break_enc" />
    <axis
      xyz="0 0 0" />
  </joint>
  <link
    name="wm4_steering_axis">
    <inertial>
      <origin
        xyz="0 0 0.051"
        rpy="0 0 0" />
      <mass
        value="0.077" />
      <inertia
        ixx="6.7067E-05"
        ixy="0"
        ixz="0"
        iyy="6.7067E-05"
        iyz="0"
        izz="0" />
    </inertial>
    <visual>
      <origin
        xyz="0 0 0"
        rpy="0 0 0" />
      <geometry>
        <mesh
          filename="file://$(find urdf_tutorial)/meshes/wm4_steering_axis.STL" />
      </geometry>
      <material
        name="">
        <color
          rgba="0.69804 0.69804 0.69804 1" />
      </material>
    </visual>
    <collision>
      <origin
        xyz="0 0 0"
        rpy="0 0 0" />
      <geometry>
        <mesh
          filename="file://$(find urdf_tutorial)/meshes/wm4_steering_axis.STL" />
      </geometry>
    </collision>
  </link>
  <joint
    name="wm4_base_to_steering_axis"
    type="revolute">
    <origin
      xyz="-0.071418 0.024749 0"
      rpy="0 0 0" />
    <parent
      link="wm4_base" />
    <child
      link="wm4_steering_axis" />
    <axis
      xyz="0 0 1" />
    <limit
      lower="-0.7854"
      upper="2.3562"
      effort="1000"
      velocity="1" />
  </joint>
  <link
    name="wm4_arm">
    <inertial>
      <origin
        xyz="0 0.045241 0.035605"
        rpy="0 0 0" />
      <mass
        value="0.227" />
      <inertia
        ixx="0.00026595"
        ixy="0"
        ixz="0"
        iyy="0.00010669"
        iyz="-2.8894E-05"
        izz="0.00025093" />
    </inertial>
    <visual>
      <origin
        xyz="0 0 0"
        rpy="0 0 0" />
      <geometry>
        <mesh
          filename="file://$(find urdf_tutorial)/meshes/wm4_arm.STL" />
      </geometry>
      <material
        name="">
        <color
          rgba="0.69804 0.69804 0.69804 1" />
      </material>
    </visual>
    <collision>
      <origin
        xyz="0 0 0"
        rpy="0 0 0" />
      <geometry>
        <mesh
          filename="file://$(find urdf_tutorial)/meshes/wm4_arm.STL" />
      </geometry>
    </collision>
  </link>
  <joint
    name="wm4_steering_axis_to_arm"
    type="fixed">
    <origin
      xyz="0 0 0"
      rpy="0 0 0" />
    <parent
      link="wm4_steering_axis" />
    <child
      link="wm4_arm" />
    <axis
      xyz="0 0 0" />
  </joint>
  <link
    name="wm4_wheel">
    <inertial>
      <origin
        xyz="0 0 0.026185"
        rpy="0 0 0" />
      <mass
        value="0.182" />
      <inertia
        ixx="8.4576E-05"
        ixy="0"
        ixz="0"
        iyy="8.4576E-05"
        iyz="0"
        izz="0.00015944" />
    </inertial>
    <visual>
      <origin
        xyz="0 0 0"
        rpy="0 0 0" />
      <geometry>
        <mesh
          filename="file://$(find urdf_tutorial)/meshes/wm4_wheel.STL" />
      </geometry>
      <material
        name="">
        <color
          rgba="0.69804 0.69804 0.69804 1" />
      </material>
    </visual>
    <collision>
      <origin
        xyz="0 0 0"
        rpy="0 0 0" />
      <geometry>
        <mesh
          filename="file://$(find urdf_tutorial)/meshes/wm4_wheel.STL" />
      </geometry>
    </collision>
  </link>
  <joint
    name="wm4_arm_to_wheel"
    type="continuous">
    <origin
      xyz="0 0.08845 0.03"
      rpy="1.5708 0 3.1416" />
    <parent
      link="wm4_arm" />
    <child
      link="wm4_wheel" />
    <axis
      xyz="0 0 -1" />
  </joint>

  <ros2_control name="GazeboSystem" type="system">
    <hardware>
      <plugin>gazebo_ros2_control/GazeboSystem</plugin>
    </hardware>

    <joint name="wm1_base_to_steering_axis">
      <command_interface name="effort">
        <param name="min">-1000</param>
        <param name="max">1000</param>
      </command_interface>
      <state_interface name="position">
        <param name="initial_value">0.0</param>
      </state_interface>
      <state_interface name="velocity"/>
      <state_interface name="effort"/>
    </joint>

    <joint name="wm1_arm_to_wheel">
      <command_interface name="effort">
        <param name="min">-1000</param>
        <param name="max">1000</param>
      </command_interface>
      <state_interface name="position">
        <param name="initial_value">0.0</param>
      </state_interface>
      <state_interface name="velocity"/>
      <state_interface name="effort"/>
    </joint>

    <joint name="wm2_base_to_steering_axis">
      <command_interface name="effort">
        <param name="min">-1000</param>
        <param name="max">1000</param>
      </command_interface>
      <state_interface name="position">
        <param name="initial_value">0.0</param>
      </state_interface>
      <state_interface name="velocity"/>
      <state_interface name="effort"/>
    </joint>

    <joint name="wm2_arm_to_wheel">
      <command_interface name="effort">
        <param name="min">-1000</param>
        <param name="max">1000</param>
      </command_interface>
      <state_interface name="position">
        <param name="initial_value">0.0</param>
      </state_interface>
      <state_interface name="velocity"/>
      <state_interface name="effort"/>
    </joint>

    <joint name="wm3_base_to_steering_axis">
      <command_interface name="effort">
        <param name="min">-1000</param>
        <param name="max">1000</param>
      </command_interface>
      <state_interface name="position">
        <param name="initial_value">0.0</param>
      </state_interface>
      <state_interface name="velocity"/>
      <state_interface name="effort"/>
    </joint>

    <joint name="wm3_arm_to_wheel">
      <command_interface name="effort">
        <param name="min">-1000</param>
        <param name="max">1000</param>
      </command_interface>
      <state_interface name="position">
        <param name="initial_value">0.0</param>
      </state_interface>
      <state_interface name="velocity"/>
      <state_interface name="effort"/>
    </joint>

    <joint name="wm4_base_to_steering_axis">
      <command_interface name="effort">
        <param name="min">-1000</param>
        <param name="max">1000</param>
      </command_interface>
      <state_interface name="position">
        <param name="initial_value">0.0</param>
      </state_interface>
      <state_interface name="velocity"/>
      <state_interface name="effort"/>
    </joint>

    <joint name="wm4_arm_to_wheel">
      <command_interface name="effort">
        <param name="min">-1000</param>
        <param name="max">1000</param>
      </command_interface>
      <state_interface name="position">
        <param name="initial_value">0.0</param>
      </state_interface>
      <state_interface name="velocity"/>
      <state_interface name="effort"/>
    </joint>

  </ros2_control>

  <gazebo>
    <plugin filename="libgazebo_ros2_control.so" name="gazebo_ros2_control">
      <parameters>$(find snow_sim)/config/snow_v3.yaml</parameters>
    </plugin>
  </gazebo>



</robot>
