<?xml version="1.0" encoding="utf-8"?>
<!-- This URDF was automatically created by SolidWorks to URDF Exporter! Originally created by Stephen Brawner (brawner@gmail.com) 
     Commit Version: 1.6.0-4-g7f85cfe  Build Version: 1.6.7995.38578
     For more information, please see http://wiki.ros.org/sw_urdf_exporter -->
<robot
  name="snowbot_simple_v4">
  <link
    name="base_link">
    <inertial>
      <origin
        xyz="-3.46944695195361E-18 2.08166817117217E-17 0.042"
        rpy="0 0 0" />
      <mass
        value="2.282808" />
      <inertia
        ixx="0.013361138208"
        ixy="4.77048955893622E-18"
        ixz="1.37909452591892E-19"
        iyy="0.013361138208"
        iyz="2.73863681771319E-19"
        izz="0.025300928752" />
    </inertial>
    <visual>
      <origin
        xyz="0 0 0"
        rpy="0 0 0" />
      <geometry>
        <mesh
          filename="file://$(find urdf_tutorial)/meshes/base_link.STL" />
      </geometry>
      <material
        name="">
        <color
          rgba="0.792156862745098 0.819607843137255 0.933333333333333 1" />
      </material>
    </visual>
    <collision>
      <origin
        xyz="0 0 0"
        rpy="0 0 0" />
      <geometry>
        <mesh
          filename="file://$(find urdf_tutorial)/meshes/base_link.STL" />
      </geometry>
    </collision>
  </link>
  <link
    name="wm1">
    <inertial>
      <origin
        xyz="0.0427351379564556 0 -0.0229933385881074"
        rpy="0 0 0" />
      <mass
        value="0.241464642114672" />
      <inertia
        ixx="9.02315680937692E-05"
        ixy="8.13151629364128E-20"
        ixz="-9.69357557072419E-08"
        iyy="0.000268550530469722"
        iyz="-5.38660014894532E-21"
        izz="0.000273896352939588" />
    </inertial>
    <visual>
      <origin
        xyz="0 0 0"
        rpy="0 0 0" />
      <geometry>
        <mesh
          filename="file://$(find urdf_tutorial)/meshes/wm1.STL" />
      </geometry>
      <material
        name="">
        <color
          rgba="0.792156862745098 0.819607843137255 0.933333333333333 1" />
      </material>
    </visual>
    <collision>
      <origin
        xyz="0 0 0"
        rpy="0 0 0" />
      <geometry>
        <mesh
          filename="file://$(find urdf_tutorial)/meshes/wm1.STL" />
      </geometry>
    </collision>
  </link>
  <joint
    name="base_to_wm1"
    type="revolute">
    <origin
      xyz="-0.12869 -0.12869 0.065"
      rpy="0 0 -1.5708" />
    <parent
      link="base_link" />
    <child
      link="wm1" />
    <axis
      xyz="0 0 1" />
    <limit
      lower="-2.36"
      upper="0.79"
      effort="1000"
      velocity="0.5" />
  </joint>
  <link
    name="wm1_wheel">
    <inertial>
      <origin
        xyz="0 0 0.00400000000000011"
        rpy="0 0 0" />
      <mass
        value="0.0486569870187987" />
      <inertia
        ixx="2.38094856478655E-05"
        ixy="-5.38549347852005E-21"
        ixz="5.9292306307801E-21"
        iyy="2.38094856478655E-05"
        iyz="1.67497481355817E-21"
        izz="4.70999634341971E-05" />
    </inertial>
    <visual>
      <origin
        xyz="0 0 0"
        rpy="0 0 0" />
      <geometry>
        <mesh
          filename="file://$(find urdf_tutorial)/meshes/wm1_wheel.STL" />
      </geometry>
      <material
        name="">
        <color
          rgba="0.792156862745098 0.819607843137255 0.933333333333333 1" />
      </material>
    </visual>
    <collision>
      <origin
        xyz="0 0 0"
        rpy="0 0 0" />
      <geometry>
        <mesh
          filename="file://$(find urdf_tutorial)/meshes/wm1_wheel.STL" />
      </geometry>
    </collision>
  </link>
  <joint
    name="wm1_to_wheel"
    type="continuous">
    <origin
      xyz="0.111 0 -0.021"
      rpy="1.5708 0 1.5708" />
    <parent
      link="wm1" />
    <child
      link="wm1_wheel" />
    <axis
      xyz="0 0 -1" />
  </joint>
  <link
    name="wm2">
    <inertial>
      <origin
        xyz="0.0427351379564556 -5.55111512312578E-17 -0.0229933385881074"
        rpy="0 0 0" />
      <mass
        value="0.241464642114672" />
      <inertia
        ixx="9.02315680937692E-05"
        ixy="1.6940658945086E-20"
        ixz="-9.69357557072334E-08"
        iyy="0.000268550530469722"
        iyz="2.4848505601093E-21"
        izz="0.000273896352939589" />
    </inertial>
    <visual>
      <origin
        xyz="0 0 0"
        rpy="0 0 0" />
      <geometry>
        <mesh
          filename="file://$(find urdf_tutorial)/meshes/wm2.STL" />
      </geometry>
      <material
        name="">
        <color
          rgba="0.792156862745098 0.819607843137255 0.933333333333333 1" />
      </material>
    </visual>
    <collision>
      <origin
        xyz="0 0 0"
        rpy="0 0 0" />
      <geometry>
        <mesh
          filename="file://$(find urdf_tutorial)/meshes/wm2.STL" />
      </geometry>
    </collision>
  </link>
  <joint
    name="base_to_wm2"
    type="revolute">
    <origin
      xyz="0.12869 -0.12869 0.065"
      rpy="0 0 -1.5708" />
    <parent
      link="base_link" />
    <child
      link="wm2" />
    <axis
      xyz="0 0 1" />
    <limit
      lower="-0.79"
      upper="2.36"
      effort="1000"
      velocity="0.5" />
  </joint>
  <link
    name="wm2_wheel">
    <inertial>
      <origin
        xyz="-1.38777878078145E-17 0 0.00399999999999989"
        rpy="0 0 0" />
      <mass
        value="0.0486569870187986" />
      <inertia
        ixx="2.38094856478654E-05"
        ixy="7.29961465462049E-22"
        ixz="1.6940658945086E-21"
        iyy="2.38094856478654E-05"
        iyz="-4.86687582809085E-22"
        izz="4.7099963434197E-05" />
    </inertial>
    <visual>
      <origin
        xyz="0 0 0"
        rpy="0 0 0" />
      <geometry>
        <mesh
          filename="file://$(find urdf_tutorial)/meshes/wm2_wheel.STL" />
      </geometry>
      <material
        name="">
        <color
          rgba="0.792156862745098 0.819607843137255 0.933333333333333 1" />
      </material>
    </visual>
    <collision>
      <origin
        xyz="0 0 0"
        rpy="0 0 0" />
      <geometry>
        <mesh
          filename="file://$(find urdf_tutorial)/meshes/wm2_wheel.STL" />
      </geometry>
    </collision>
  </link>
  <joint
    name="wm2_to_wheel"
    type="continuous">
    <origin
      xyz="0.111 0 -0.021"
      rpy="1.5708 0 1.5708" />
    <parent
      link="wm2" />
    <child
      link="wm2_wheel" />
    <axis
      xyz="0 0 -1" />
  </joint>
  <link
    name="wm3">
    <inertial>
      <origin
        xyz="0.0427351379564557 -6.93889390390723E-17 -0.0229933385881074"
        rpy="0 0 0" />
      <mass
        value="0.241464642114672" />
      <inertia
        ixx="9.02315680937692E-05"
        ixy="2.71050543121376E-20"
        ixz="-9.69357557072119E-08"
        iyy="0.000268550530469722"
        iyz="1.36120841601726E-20"
        izz="0.000273896352939589" />
    </inertial>
    <visual>
      <origin
        xyz="0 0 0"
        rpy="0 0 0" />
      <geometry>
        <mesh
          filename="file://$(find urdf_tutorial)/meshes/wm3.STL" />
      </geometry>
      <material
        name="">
        <color
          rgba="0.792156862745098 0.819607843137255 0.933333333333333 1" />
      </material>
    </visual>
    <collision>
      <origin
        xyz="0 0 0"
        rpy="0 0 0" />
      <geometry>
        <mesh
          filename="file://$(find urdf_tutorial)/meshes/wm3.STL" />
      </geometry>
    </collision>
  </link>
  <joint
    name="base_to_wm3"
    type="revolute">
    <origin
      xyz="0.12869 0.12869 0.065"
      rpy="0 0 1.5708" />
    <parent
      link="base_link" />
    <child
      link="wm3" />
    <axis
      xyz="0 0 1" />
    <limit
      lower="-2.36"
      upper="0.79"
      effort="1000"
      velocity="0.5" />
  </joint>
  <link
    name="wm3_wheel">
    <inertial>
      <origin
        xyz="2.77555756156289E-17 0 0.00399999999999998"
        rpy="0 0 0" />
      <mass
        value="0.0486569870187988" />
      <inertia
        ixx="2.38094856478655E-05"
        ixy="5.12844721888724E-22"
        ixz="5.0821976835258E-21"
        iyy="2.38094856478655E-05"
        iyz="3.00079622659877E-22"
        izz="4.70999634341972E-05" />
    </inertial>
    <visual>
      <origin
        xyz="0 0 0"
        rpy="0 0 0" />
      <geometry>
        <mesh
          filename="file://$(find urdf_tutorial)/meshes/wm3_wheel.STL" />
      </geometry>
      <material
        name="">
        <color
          rgba="0.792156862745098 0.819607843137255 0.933333333333333 1" />
      </material>
    </visual>
    <collision>
      <origin
        xyz="0 0 0"
        rpy="0 0 0" />
      <geometry>
        <mesh
          filename="file://$(find urdf_tutorial)/meshes/wm3_wheel.STL" />
      </geometry>
    </collision>
  </link>
  <joint
    name="wm3_to_wheel"
    type="continuous">
    <origin
      xyz="0.111 0 -0.021"
      rpy="1.5708 0 1.5708" />
    <parent
      link="wm3" />
    <child
      link="wm3_wheel" />
    <axis
      xyz="0 0 -1" />
  </joint>
  <link
    name="wm4">
    <inertial>
      <origin
        xyz="0.0427351379564557 -5.55111512312578E-17 -0.0229933385881074"
        rpy="0 0 0" />
      <mass
        value="0.241464642114672" />
      <inertia
        ixx="9.02315680937692E-05"
        ixy="6.7762635780344E-20"
        ixz="-9.69357557072347E-08"
        iyy="0.000268550530469722"
        iyz="4.92999645081604E-21"
        izz="0.000273896352939589" />
    </inertial>
    <visual>
      <origin
        xyz="0 0 0"
        rpy="0 0 0" />
      <geometry>
        <mesh
          filename="file://$(find urdf_tutorial)/meshes/wm4.STL" />
      </geometry>
      <material
        name="">
        <color
          rgba="0.792156862745098 0.819607843137255 0.933333333333333 1" />
      </material>
    </visual>
    <collision>
      <origin
        xyz="0 0 0"
        rpy="0 0 0" />
      <geometry>
        <mesh
          filename="file://$(find urdf_tutorial)/meshes/wm4.STL" />
      </geometry>
    </collision>
  </link>
  <joint
    name="base_to_wm4"
    type="revolute">
    <origin
      xyz="-0.12869 0.12869 0.065"
      rpy="0 0 1.5708" />
    <parent
      link="base_link" />
    <child
      link="wm4" />
    <axis
      xyz="0 0 1" />
    <limit
      lower="-0.79"
      upper="2.36"
      effort="1000"
      velocity="0.5" />
  </joint>
  <link
    name="wm4_wheel">
    <inertial>
      <origin
        xyz="0 -3.46944695195361E-18 0.00399999999999998"
        rpy="0 0 0" />
      <mass
        value="0.0486569870187986" />
      <inertia
        ixx="2.38094856478655E-05"
        ixy="9.0434114887799E-22"
        ixz="1.6940658945086E-21"
        iyy="2.38094856478655E-05"
        iyz="-6.46590024811317E-22"
        izz="4.70999634341971E-05" />
    </inertial>
    <visual>
      <origin
        xyz="0 0 0"
        rpy="0 0 0" />
      <geometry>
        <mesh
          filename="file://$(find urdf_tutorial)/meshes/wm4_wheel.STL" />
      </geometry>
      <material
        name="">
        <color
          rgba="0.792156862745098 0.819607843137255 0.933333333333333 1" />
      </material>
    </visual>
    <collision>
      <origin
        xyz="0 0 0"
        rpy="0 0 0" />
      <geometry>
        <mesh
          filename="file://$(find urdf_tutorial)/meshes/wm4_wheel.STL" />
      </geometry>
    </collision>
  </link>
  <joint
    name="wm4_to_wheel"
    type="continuous">
    <origin
      xyz="0.111 0 -0.021"
      rpy="1.5708 0 1.5708" />
    <parent
      link="wm4" />
    <child
      link="wm4_wheel" />
    <axis
      xyz="0 0 -1" />
  </joint>
</robot>
